Workbook

Sheet Queue
A1: ID | B1: Name_TH | C1: Name_EN | D1: Photo_URL | E1: Working_Today
A2: 1 | B2: ภา | C2: Pa | E2: ทำงาน
A3: 2 | B3: เมล | C3: Mel | E3: ทำงาน
A5: คำอธิบาย:
A6: แท็บนี้เก็บแค่ข้อมูลประจำตัวหมอนวด (ชื่อ/รูป) เพิ่มแถวได้เมื่อมีหมอนวดคนใหม่
A7: ID ต้องไม่ซ้ำกัน และต้องตรงกับคอลัมน์ Therapist_ID ในแท็บ "ตารางเวลาหมอนวด"
A8: สถานะว่าง/ไม่ว่าง และคิวถัดไป จะถูกคำนวณอัตโนมัติจากแท็บ "ตารางเวลาหมอนวด" ไม่ต้องกรอกในแท็บนี้แล้ว
A9: Working_Today: ใส่ "ทำงาน" ตามปกติ ถ้าหมอนวดคนไหนลา/ไม่มาทำงานวันนี้ ให้เปลี่ยนเป็น "ไม่ทำงาน" (มีดรอปดาวน์ในคอลัมน์ E) การ์ดจะขึ้นเป็น "หยุดวันนี้" แทนสถานะว่าง/ไม่ว่างทันที
A10: อย่าลืมเปลี่ยนกลับเป็น "ทำงาน" เมื่อหมอนวดกลับมาทำงานตามปกติ (คอลัมน์นี้ไม่ได้ถูกรีเซ็ตอัตโนมัติทุกวัน ต้องแก้เองตามตารางเข้างานจริง)

Sheet ตารางเวลาหมอนวด
A1: Therapist_ID | B1: Time_Slot | C1: Status | D1: Customer_Note | E1: ห้อง | F1: เบอร์โทร | G1: คอร์สการนวด | H1: ชั่วโมง | I1: ราคา | J1: ประเภทลูกค้า | K1: หมายเหตุ | L1: เวลาเริ่มจริง | M1: เวลาสิ้นสุดจริง
A2: 1 | B2: 12:00 | C2: ไม่ว่าง | D2: คุณน้อย | E2: 205 | F2: 0894360716 | G2: นวดแผนไทย | H2: =IFERROR(VLOOKUP(G2,ราคาคอร์ส!$A:$C,2,FALSE)/60,"") | I2: =IFERROR(VLOOKUP(G2,ราคาคอร์ส!$A:$C,3,FALSE),"") | J2: Walk-in
A3: 1 | B3: 13:00 | C3: ไม่ว่าง | H3: =IFERROR(VLOOKUP(G3,ราคาคอร์ส!$A:$C,2,FALSE)/60,"") | I3: =IFERROR(VLOOKUP(G3,ราคาคอร์ส!$A:$C,3,FALSE),"")
A4: 1 | B4: 14:00 | C4: ว่าง | H4: =IFERROR(VLOOKUP(G4,ราคาคอร์ส!$A:$C,2,FALSE)/60,"") | I4: =IFERROR(VLOOKUP(G4,ราคาคอร์ส!$A:$C,3,FALSE),"")
A5: 1 | B5: 15:00 | C5: ว่าง | H5: =IFERROR(VLOOKUP(G5,ราคาคอร์ส!$A:$C,2,FALSE)/60,"") | I5: =IFERROR(VLOOKUP(G5,ราคาคอร์ส!$A:$C,3,FALSE),"")
A6: 1 | B6: 16:00 | C6: ว่าง | H6: =IFERROR(VLOOKUP(G6,ราคาคอร์ส!$A:$C,2,FALSE)/60,"") | I6: =IFERROR(VLOOKUP(G6,ราคาคอร์ส!$A:$C,3,FALSE),"")
A7: 1 | B7: 17:00 | C7: ว่าง | H7: =IFERROR(VLOOKUP(G7,ราคาคอร์ส!$A:$C,2,FALSE)/60,"") | I7: =IFERROR(VLOOKUP(G7,ราคาคอร์ส!$A:$C,3,FALSE),"")
A8: 1 | B8: 18:00 | C8: ว่าง | H8: =IFERROR(VLOOKUP(G8,ราคาคอร์ส!$A:$C,2,FALSE)/60,"") | I8: =IFERROR(VLOOKUP(G8,ราคาคอร์ส!$A:$C,3,FALSE),"")
A9: 1 | B9: 19:00 | C9: ว่าง | H9: =IFERROR(VLOOKUP(G9,ราคาคอร์ส!$A:$C,2,FALSE)/60,"") | I9: =IFERROR(VLOOKUP(G9,ราคาคอร์ส!$A:$C,3,FALSE),"")
A10: 1 | B10: 20:00 | C10: ว่าง | H10: =IFERROR(VLOOKUP(G10,ราคาคอร์ส!$A:$C,2,FALSE)/60,"") | I10: =IFERROR(VLOOKUP(G10,ราคาคอร์ส!$A:$C,3,FALSE),"")
A11: 1 | B11: 21:00 | C11: ว่าง | H11: =IFERROR(VLOOKUP(G11,ราคาคอร์ส!$A:$C,2,FALSE)/60,"") | I11: =IFERROR(VLOOKUP(G11,ราคาคอร์ส!$A:$C,3,FALSE),"")
A12: 1 | B12: 22:00 | C12: ไม่ว่าง | D12: คุณศุประภาภรณ์ | F12: 0927184289 | G12: นวดฝ่าเท้า | H12: =IFERROR(VLOOKUP(G12,ราคาคอร์ส!$A:$C,2,FALSE)/60,"") | I12: =IFERROR(VLOOKUP(G12,ราคาคอร์ส!$A:$C,3,FALSE),"") | J12: ลูกค้าโรงแรม
A13: 1 | B13: 23:00 | C13: ว่าง | H13: =IFERROR(VLOOKUP(G13,ราคาคอร์ส!$A:$C,2,FALSE)/60,"") | I13: =IFERROR(VLOOKUP(G13,ราคาคอร์ส!$A:$C,3,FALSE),"")
A14: 2 | B14: 12:00 | C14: ว่าง | H14: =IFERROR(VLOOKUP(G14,ราคาคอร์ส!$A:$C,2,FALSE)/60,"") | I14: =IFERROR(VLOOKUP(G14,ราคาคอร์ส!$A:$C,3,FALSE),"")
A15: 2 | B15: 13:00 | C15: ว่าง | H15: =IFERROR(VLOOKUP(G15,ราคาคอร์ส!$A:$C,2,FALSE)/60,"") | I15: =IFERROR(VLOOKUP(G15,ราคาคอร์ส!$A:$C,3,FALSE),"")
A16: 2 | B16: 14:00 | C16: ว่าง | H16: =IFERROR(VLOOKUP(G16,ราคาคอร์ส!$A:$C,2,FALSE)/60,"") | I16: =IFERROR(VLOOKUP(G16,ราคาคอร์ส!$A:$C,3,FALSE),"")
A17: 2 | B17: 15:00 | C17: ว่าง | H17: =IFERROR(VLOOKUP(G17,ราคาคอร์ส!$A:$C,2,FALSE)/60,"") | I17: =IFERROR(VLOOKUP(G17,ราคาคอร์ส!$A:$C,3,FALSE),"")
A18: 2 | B18: 16:00 | C18: ว่าง | H18: =IFERROR(VLOOKUP(G18,ราคาคอร์ส!$A:$C,2,FALSE)/60,"") | I18: =IFERROR(VLOOKUP(G18,ราคาคอร์ส!$A:$C,3,FALSE),"")
A19: 2 | B19: 17:00 | C19: ไม่ว่าง | D19: คุณโชค | G19: นวดฝ่าเท้า | H19: =IFERROR(VLOOKUP(G19,ราคาคอร์ส!$A:$C,2,FALSE)/60,"") | I19: =IFERROR(VLOOKUP(G19,ราคาคอร์ส!$A:$C,3,FALSE),"") | J19: Walk-in | L19: 17:12 | M19: 18:42
A20: 2 | B20: 18:00 | C20: ว่าง | H20: =IFERROR(VLOOKUP(G20,ราคาคอร์ส!$A:$C,2,FALSE)/60,"") | I20: =IFERROR(VLOOKUP(G20,ราคาคอร์ส!$A:$C,3,FALSE),"")
A21: 2 | B21: 19:00 | C21: ว่าง | H21: =IFERROR(VLOOKUP(G21,ราคาคอร์ส!$A:$C,2,FALSE)/60,"") | I21: =IFERROR(VLOOKUP(G21,ราคาคอร์ส!$A:$C,3,FALSE),"")
A22: 2 | B22: 20:00 | C22: ว่าง | H22: =IFERROR(VLOOKUP(G22,ราคาคอร์ส!$A:$C,2,FALSE)/60,"") | I22: =IFERROR(VLOOKUP(G22,ราคาคอร์ส!$A:$C,3,FALSE),"")
A23: 2 | B23: 21:00 | C23: ว่าง | H23: =IFERROR(VLOOKUP(G23,ราคาคอร์ส!$A:$C,2,FALSE)/60,"") | I23: =IFERROR(VLOOKUP(G23,ราคาคอร์ส!$A:$C,3,FALSE),"")
A24: 2 | B24: 22:00 | C24: ว่าง | H24: =IFERROR(VLOOKUP(G24,ราคาคอร์ส!$A:$C,2,FALSE)/60,"") | I24: =IFERROR(VLOOKUP(G24,ราคาคอร์ส!$A:$C,3,FALSE),"")
A25: 2 | B25: 23:00 | C25: ว่าง | H25: =IFERROR(VLOOKUP(G25,ราคาคอร์ส!$A:$C,2,FALSE)/60,"") | I25: =IFERROR(VLOOKUP(G25,ราคาคอร์ส!$A:$C,3,FALSE),"")
H26: =IFERROR(VLOOKUP(G26,ราคาคอร์ส!$A:$C,2,FALSE)/60,"") | I26: =IFERROR(VLOOKUP(G26,ราคาคอร์ส!$A:$C,3,FALSE),"")
A27: คำอธิบาย: | H27: =IFERROR(VLOOKUP(G27,ราคาคอร์ส!$A:$C,2,FALSE)/60,"") | I27: =IFERROR(VLOOKUP(G27,ราคาคอร์ส!$A:$C,3,FALSE),"")
A28: ตารางนี้สร้างแถวไว้ให้ล่วงหน้าทุกชั่วโมง (12:00-23:00) ต่อหมอนวด 1 คน แค่เปลี่ยน Status เป็น "ไม่ว่าง" แล้วกรอกรายละเอียดตามจริง | H28: =IFERROR(VLOOKUP(G28,ราคาคอร์ส!$A:$C,2,FALSE)/60,"") | I28: =IFERROR(VLOOKUP(G28,ราคาคอร์ส!$A:$C,3,FALSE),"")
A29: ราคา: ใส่ราคาที่ขายจริงของคิวนั้น (บาท) เก็บไว้ในแถวเดียวกับการจอง ใช้สำหรับงานบัญชี/สรุปยอดขาย ไม่ถูกใช้คำนวณอะไรบนจอแสดงผล | H29: =IFERROR(VLOOKUP(G29,ราคาคอร์ส!$A:$C,2,FALSE)/60,"") | I29: =IFERROR(VLOOKUP(G29,ราคาคอร์ส!$A:$C,3,FALSE),"")
A30: ถ้าคอร์สที่ใช้เวลานานกว่า 1 ชั่วโมง ให้เปลี่ยน Status เป็น "ไม่ว่าง" ในแถวชั่วโมงถัดๆ ไปด้วย ปล่อย Customer_Note ว่างไว้ในแถวต่อเนื่อง ระบบจะรวมเป็นคิวเดียวกันอัตโนมัติ (กรอกราคาแค่แถวแรกพอ) | H30: =IFERROR(VLOOKUP(G30,ราคาคอร์ส!$A:$C,2,FALSE)/60,"") | I30: =IFERROR(VLOOKUP(G30,ราคาคอร์ส!$A:$C,3,FALSE),"")
A31: เวลาเริ่มจริง / เวลาสิ้นสุดจริง: ช่องเสริมไม่บังคับ สำหรับตอนลูกค้าเข้าไม่ตรงชั่วโมงเป๊ะ | H31: =IFERROR(VLOOKUP(G31,ราคาคอร์ส!$A:$C,2,FALSE)/60,"") | I31: =IFERROR(VLOOKUP(G31,ราคาคอร์ส!$A:$C,3,FALSE),"")
A32: Therapist_ID: 1 = ภา, 2 = เมล | H32: =IFERROR(VLOOKUP(G32,ราคาคอร์ส!$A:$C,2,FALSE)/60,"") | I32: =IFERROR(VLOOKUP(G32,ราคาคอร์ส!$A:$C,3,FALSE),"")
A33: ตารางนี้ไม่มีคอลัมน์วันที่ เพราะรีเซ็ตอัตโนมัติทุกเที่ยงคืนผ่าน Apps Script | H33: =IFERROR(VLOOKUP(G33,ราคาคอร์ส!$A:$C,2,FALSE)/60,"") | I33: =IFERROR(VLOOKUP(G33,ราคาคอร์ส!$A:$C,3,FALSE),"")
H34: =IFERROR(VLOOKUP(G34,ราคาคอร์ส!$A:$C,2,FALSE)/60,"") | I34: =IFERROR(VLOOKUP(G34,ราคาคอร์ส!$A:$C,3,FALSE),"")
H35: =IFERROR(VLOOKUP(G35,ราคาคอร์ส!$A:$C,2,FALSE)/60,"") | I35: =IFERROR(VLOOKUP(G35,ราคาคอร์ส!$A:$C,3,FALSE),"")
H36: =IFERROR(VLOOKUP(G36,ราคาคอร์ส!$A:$C,2,FALSE)/60,"") | I36: =IFERROR(VLOOKUP(G36,ราคาคอร์ส!$A:$C,3,FALSE),"")
H37: =IFERROR(VLOOKUP(G37,ราคาคอร์ส!$A:$C,2,FALSE)/60,"") | I37: =IFERROR(VLOOKUP(G37,ราคาคอร์ส!$A:$C,3,FALSE),"")
H38: =IFERROR(VLOOKUP(G38,ราคาคอร์ส!$A:$C,2,FALSE)/60,"") | I38: =IFERROR(VLOOKUP(G38,ราคาคอร์ส!$A:$C,3,FALSE),"")
H39: =IFERROR(VLOOKUP(G39,ราคาคอร์ส!$A:$C,2,FALSE)/60,"") | I39: =IFERROR(VLOOKUP(G39,ราคาคอร์ส!$A:$C,3,FALSE),"")
H40: =IFERROR(VLOOKUP(G40,ราคาคอร์ส!$A:$C,2,FALSE)/60,"") | I40: =IFERROR(VLOOKUP(G40,ราคาคอร์ส!$A:$C,3,FALSE),"")
...

Sheet Settings
A1: Key | B1: Value
A2: ShopName_TH | B2: ยินดีต้อนรับสู่บริการสปา
A3: ShopName_EN | B3: Welcome to Our Spa
A4: Tagline_TH | B4: กรุณาตรวจสอบคิวว่างของหมอนวด
A5: ContactLabel_TH | B5: สอบถามข้อมูลเพิ่มเติม
A6: Phone | B6: 02-123-4567

Sheet เช็คคิวว่าง
B2: 🔍 เช็คคิวว่างของหมอนวด
B4: หมอนวด:
B5: เวลาเริ่ม (เช่น 14:00):
B6: เวลาสิ้นสุด (เช่น 15:30):
B8: ผลลัพธ์: | C8: =IF(OR(C4="",C5="",C6=""),"⬅ กรอกข้อมูลให้ครบก่อน",CHECK_QUEUE(C4,C5,C6))
B11: วิธีใช้: เลือกหมอนวด กรอกเวลาเริ่ม-สิ้นสุด แล้วดูผลลัพธ์ด้านบน ไม่กระทบข้อมูลในแท็บ "ตารางเวลาหมอนวด" แต่อย่างใด ต้องอัปเดตฟังก์ชัน CHECK_QUEUE ใน Apps Script เป็นเวอร์ชันใหม่ก่อนใช้งานได้ (ดูโค้ดในแชท) เพราะโครงสร้างตารางเปลี่ยนไป

Sheet ราคาคอร์ส
A1: คอร์สการนวด | B1: ระยะเวลา (นาที) | C1: ราคา (บาท)
A2: นวดน้ำมันขิงร้อน | B2: 60 | C2: 900
A3: นวดน้ำมันทองคำ | B3: 90 | C3: 1400
A4: นวดน้ำมันอโรมา | B4: 60 | C4: 900
A5: นวดคอ บ่า ไหล่ | B5: 30 | C5: 500
A6: 42C Treatment | B6: 120 | C6: 2200
A7: สครับผิวเกลือสปา | B7: 60 | C7: 800
A8: ขัดผิว+มาร์ค+นวดน้ำมันอโรมา | B8: 120 | C8: 1800
A9: นวดแผนไทย | B9: 60 | C9: 600
A10: นวดฝ่าเท้า | B10: 60 | C10: 500
A12: คำอธิบาย:
A13: ตารางนี้เป็นราคามาตรฐานอ้างอิงของแต่ละคอร์ส แก้ตัวเลขราคา/เวลาให้ตรงกับร้านจริงได้เลย
A14: รายชื่อคอร์สตรงกับ dropdown "คอร์สการนวด" ในแท็บ "ตารางเวลาหมอนวด" พอดี ถ้าเพิ่ม/ลบคอร์สในตารางนี้ อย่าลืมไปแก้ dropdown ในแท็บนั้นให้ตรงกันด้วย
A15: ตารางนี้ไม่ได้เชื่อมกับหน้าจอแสดงผล (จอไม่ได้อ่านราคา) ใช้เป็นข้อมูลอ้างอิงสำหรับพนักงาน/บัญชีเท่านั้น
